[
 {
  "Error": {},
  "Frames": [
   {
    "Time": 41,
    "Turn": 0
   },
   {
    "Commands": [
     {
      "angle": 84,
      "magnitude": 3,
      "owner": 0,
      "queue_number": 0,
      "shipId": 2,
      "type": "thrust"
     },
     {
      "angle": 122,
      "magnitude": 3,
      "owner": 0,
      "queue_number": 0,
      "shipId": 1,
      "type": "thrust"
     },
     {
      "angle": 125,
      "magnitude": 3,
      "owner": 0,
      "queue_number": 0,
      "shipId": 0,
      "type": "thrust"
     }
    ],
    "Planets": null,
    "Ships": [
     {
      "cooldown": 0,
      "docking": {
       "status": "undocked"
      },
      "health": 255,
      "id": 2,
      "owner": 0,
      "vel_x": 0.0,
      "vel_y": 0.0,
      "x": 120.313585389803,
      "y": 45.9835656861048
     },
     {
      "cooldown": 0,
      "docking": {
       "status": "undocked"
      },
      "health": 255,
      "id": 1,
      "owner": 0,
      "vel_x": 0.0,
      "vel_y": 0.0,
      "x": 118.4102422073,
      "y": 39.5441442884693
     },
     {
      "cooldown": 0,
      "docking": {
       "status": "undocked"
      },
      "health": 255,
      "id": 0,
      "owner": 0,
      "vel_x": 0.0,
      "vel_y": 0.0,
      "x": 118.279270690947,
      "y": 42.457456132867
     }
    ],
    "Time": 9,
    "Turn": 1
   }
  ],
  "PlayerID": 0,
  "PlayerName": "loopcore"
 },
 {
  "Error": {
   "Message": "ERRORED! Got Exception (if any): ERROR: Bot #1: Received invalid character '  File \"MyBot.py\", line 21, in <module>F'. (at character 3.)\nInput received from bot:\n  File \"MyBot.py\", line 21, in <module>\n  ^; Response received (if any):   File \"MyBot.py\", line 21, in <module>    game = hlt.Game(\"Settler\")  File \"/home/crawforc3/projects/halite/hlt/networking.py\", line 78, in __init__    Game._set_up_logging(tag, name)  File \"/home/crawforc3/projects/halite/hlt/networking.py\", line 68, in _set_up_logging    logging.basicConfig(filename=log_file, level=logging.DEBUG, filemode='w')  File \"/home/crawforc3/anaconda3/lib/python3.6/logging/__init__.py\", line 1781, in basicConfig    h = FileHandler(filename, mode)  File \"/home/crawforc3/anaconda3/lib/python3.6/logging/__init__.py\", line 1030, in __init__    StreamHandler.__init__(self, self._open())  File \"/home/crawforc3/anaconda3/lib/python3.6/logging/__init__.py\", line 1059, in _open    return open(self.baseFilename, self.mode, encoding=self.encoding)PermissionError: [Errno 13] Permission denied: '/home/crawforc3/projects/halite/1_Settler.log'",
   "Turn": 1
  },
  "Frames": [
   {
    "Time": 37,
    "Turn": 0
   },
   {
    "Time": 0
   }
  ],
  "PlayerID": 1,
  "PlayerName": "Traceback (most recent call la"
 }
]
